<?xml version='1.0'?>
<robot name="myrobot">

  <!-- Base Link -->
  <link name="base_link">
    <visual>
      <origin xyz="-0.195 0 0" rpy="0 0 0" />
      <geometry>
          <box size="0.505 0.54 0.02"/>
      </geometry>
      <material name="blue">
        <color rgba="0 1 1 1"/>
      </material>
    </visual>
    <!-- Base collision, mass and inertia -->
    <collision>
      <origin xyz="-0.195 0 0" rpy="0 0 0" />
      <geometry>
          <box size="0.505 0.54 0.02"/>
      </geometry>
    </collision>
    <inertial>
      <mass value="10"/>
      <inertia ixx="0.36" ixy="0.0" ixz="0.0" iyy="0.31" iyz="0.0" izz="0.67"/>
    </inertial>
    <!--fronthead-->
    <visual name="fronthead">
      <origin xyz="0.05 0 0.01" rpy="0 0 0" />
      <geometry>
        <box size="0.2 0.34 0.005"/>
      </geometry>
    </visual>
    <!-- fronthead collision, mass and inertia -->
    <collision>
      <origin xyz="0.05 0 0.01" rpy="0 0 0" />
      <geometry>
        <box size="0.2 0.34 0.005"/>
      </geometry>
    </collision>
    <inertial>
      <mass value="0.4"/>
      <inertia ixx="0.004" ixy="0.0" ixz="0.0" iyy="0.001" iyz="0.0" izz="0.005"/>
    </inertial>
    <!--laserbase-->
    <visual name="laserbase">
      <origin xyz="0 0 0.152" rpy="0 0 0" />
      <geometry>
        <box size="0.02 0.02 0.3"/>
      </geometry>
    </visual>
    <!-- laserbase collision, mass and inertia -->
    <collision>
      <origin xyz="0 0 0.152" rpy="0 0 0" />
      <geometry>
        <box size="0.02 0.02 0.3"/>
      </geometry>
    </collision>
    <inertial>
      <mass value="0.3"/>
      <inertia ixx="0.002" ixy="0.0" ixz="0.0" iyy="0.002" iyz="0.0" izz="0.000"/>
    </inertial>
    <!--laserplate-->
    <visual name="laserplate">
      <origin xyz="0 0 0.302" rpy="0 0 0" />
      <geometry>
        <box size="0.2 0.2 0.005"/>
      </geometry>
    </visual>
    <!-- laserplate collision, mass and inertia -->
    <collision>
      <origin xyz="0 0 0.302" rpy="0 0 0" />
      <geometry>
        <box size="0.2 0.2 0.005"/>
      </geometry>
    </collision>
    <inertial>
      <mass value="0.24"/>
      <inertia ixx="0.000" ixy="0.0" ixz="0.0" iyy="0.000" iyz="0.0" izz="0.002"/>
    </inertial>



  </link>

  <!-- Caster 1-->
<link name="Caster1">
  <!-- Caster -->
  <visual >
    <origin xyz="-0.40 0 -0.04" rpy="0 0 0" />
    <geometry>
      <cylinder length="0.04975" radius="0.006" />
    </geometry>
  </visual>
  <!-- Caster collision, mass and inertia -->
  <collision>
    <origin xyz="-0.40 0 -0.04" rpy="0 0 0" />
    <geometry>
      <cylinder length="0.04975" radius="0.006" />
    </geometry>
  </collision>
  <inertial>
    <mass value="1"/>
    <inertia ixx="0.0001" ixy="0.0" ixz="0.0" iyy="0.0001" iyz="0.0" izz="0.0001"/>
  </inertial>
</link>

<joint name="joint_caster1" type="fixed">
  <parent link="base_link"/>
  <child link="Caster1"/>
  <origin xyz="0 0 0" rpy="0 0 0" />
  <axis xyz="0 1 0" />
  <limit effort="10000" velocity="1000"/>
  <joint_properties damping="10.0" friction="1.0"/>
</joint>

<!-- Caster 2-->
<link name="Caster2">
  <visual >
    <origin xyz="0.1 0 -0.04" rpy="0 0 0" />
    <geometry>
      <cylinder length="0.04975" radius="0.006" />
    </geometry>
  </visual>
  <!-- Caster collision, mass and inertia -->
  <collision>
    <origin xyz="0.1 0 -0.04" rpy="0 0 0" />
    <geometry>
      <cylinder length="0.04975" radius="0.006" />
    </geometry>
  </collision>
  <inertial>
    <mass value="1"/>
    <inertia ixx="0.0001" ixy="0.0" ixz="0.0" iyy="0.0001" iyz="0.0" izz="0.0001"/>
  </inertial>
</link>

<joint name="joint_caster2" type="fixed">
  <parent link="base_link"/>
  <child link="Caster2"/>
  <origin xyz="0 0 0" rpy="0 0 0" />
  <axis xyz="0 1 0" />
  <limit effort="10000" velocity="1000"/>
  <joint_properties damping="10.0" friction="1.0"/>
</joint>
       <!-- Right Wheel -->
       <link name="right_wheel">
         <visual>
           <origin xyz="0 0 0" rpy="1.570795 0 0" />
           <geometry>
               <cylinder length="0.01" radius="0.065" />
           </geometry>
           <material name="darkgray">
             <color rgba=".1 .1 .2 1"/>
           </material>
         </visual>
         <!-- Right Wheel collision, mass and inertia -->
         <collision>
           <origin xyz="0 0 0" rpy="1.570795 0 0" />
           <geometry>
               <cylinder length="0.01" radius="0.065" />
           </geometry>
         </collision>
         <inertial>
           <mass value="0.1"/>
           <inertia ixx="0.0003" ixy="0.0" ixz="0.0" iyy="0.0003" iyz="0.0" izz="0.0007"/>
         </inertial>

       </link>

       <!-- Right Wheel joint -->
       <joint name="joint_right_wheel" type="continuous">
         <parent link="base_link"/>
         <child link="right_wheel"/>
         <origin xyz="0 -0.28 0" rpy="0 0 0" />
         <axis xyz="0 1 0" />
         <limit effort="10000" velocity="1000"/>
         <joint_properties damping="10.0" friction="1.0"/>
       </joint>

       <!-- Left Wheel -->
       <link name="left_wheel">
         <visual>
           <origin xyz="0 0 0" rpy="1.570795 0 0" />
           <geometry>
               <cylinder length="0.01" radius="0.065" />
           </geometry>
           <material name="darkgray">
             <color rgba=".2 .2 .2 1"/>
           </material>
         </visual>
         <!-- Left Wheel collision, mass and inertia -->
         <collision>
           <origin xyz="0 0 0" rpy="1.570795 0 0" />
           <geometry>
               <cylinder length="0.01" radius="0.065" />
           </geometry>
         </collision>
         <inertial>
           <mass value="0.1"/>
           <inertia ixx="0.0003" ixy="0.0" ixz="0.0" iyy="0.0003" iyz="0.0" izz="0.0007"/>
         </inertial>
       </link>

       <!-- Left Wheel joint -->
       <joint name="joint_left_wheel" type="continuous">
         <parent link="base_link"/>
         <child link="left_wheel"/>
         <origin xyz="0 0.28 0" rpy="0 0 0" />
         <axis xyz="0 1 0" />
         <limit effort="10000" velocity="1000"/>
         <joint_properties damping="10.0" friction="1.0"/>
       </joint>

         <!--kinect-->
         <link name="camera_link">
           <collision>
             <origin xyz="0 0 0" rpy="0 0 0"/>
             <geometry>
               <box size="0.1 0.1 0.1"/>
             </geometry>
           </collision>

           <visual>
             <origin xyz="0 0 0" rpy="0 0 1.57"/>
             <geometry>
               <mesh filename="package://husky_description/meshes/accessories/kinect.dae"/>
             </geometry>
             <material name="black"/>
           </visual>

           <inertial>
             <mass value="1e-5" />
             <inertia ixx="1e-6" ixy="0" ixz="0" iyy="1e-6" iyz="0" izz="1e-6" />
           </inertial>
         </link>

         <!--kinect joint-->
         <joint name="camera_joint" type="fixed">
           <origin xyz="0.05 0 0.04" rpy="0 0 0"/>
           <parent link="base_link"/>
           <child link="camera_link"/>
         </joint>

         <!--kinect gazebo-->
         <gazebo reference="camera_link">
             <sensor type="depth" name="camera1">
                 <always_on>1</always_on>
                 <visualize>true</visualize>
                 <camera>
                     <horizontal_fov>1.047</horizontal_fov>
                     <image>
                         <width>640</width>
                         <height>480</height>
                         <format>R8G8B8</format>
                     </image>
                     <depth_camera>

                     </depth_camera>
                     <clip>
                         <near>0.1</near>
                         <far>100</far>
                     </clip>
                 </camera>
                      <plugin name="camera_controller" filename="libgazebo_ros_openni_kinect.so">
                      <alwaysOn>true</alwaysOn>
                         <updateRate>10.0</updateRate>
                         <cameraName>camera</cameraName>
                         <frameName>camera_link</frameName>
                     <imageTopicName>rgb/image_raw</imageTopicName>
                     <depthImageTopicName>depth/image_raw</depthImageTopicName>
                     <pointCloudTopicName>depth/points</pointCloudTopicName>
                     <cameraInfoTopicName>rgb/camera_info</cameraInfoTopicName>
                     <depthImageCameraInfoTopicName>depth/camera_info</depthImageCameraInfoTopicName>
                     <pointCloudCutoff>0.4</pointCloudCutoff>
                         <hackBaseline>0.07</hackBaseline>
                         <distortionK1>0.0</distortionK1>
                         <distortionK2>0.0</distortionK2>
                         <distortionK3>0.0</distortionK3>
                         <distortionT1>0.0</distortionT1>
                         <distortionT2>0.0</distortionT2>
                     <CxPrime>0.0</CxPrime>
                     <Cx>0.0</Cx>
                     <Cy>0.0</Cy>
                     <focalLength>0.0</focalLength>
                     </plugin>
             </sensor>
           </gazebo>
             <!-- Hokuyo Laser -->

         <!--Laser-->
         <link name="hokuyo_link">
               <collision>
                 <origin xyz="0 0 0" rpy="0 0 0"/>
                 <geometry>
               <box size="0.1 0.1 0.1"/>
                 </geometry>
               </collision>

               <visual>
                 <origin xyz="0 0 0" rpy="1.57 0 3.14"/>
                 <geometry>
                   <mesh filename="package://delf/meshes/rplidar.dae"/>
                 </geometry>
               </visual>

               <inertial>
                 <mass value="1e-5" />
                 <inertia ixx="1e-6" ixy="0" ixz="0" iyy="1e-6" iyz="0" izz="1e-6" />
               </inertial>
             </link>

         <!--Laser joint-->
         <joint name="hokuyo_joint" type="fixed">
               <origin xyz="-0.05 0 .325" rpy="0 0 0"/>
               <parent link="base_link"/>
               <child link="hokuyo_link"/>
         </joint>

         <!--Laser gazebo-->
         <gazebo reference="hokuyo_link">
           <sensor type ="ray" name="hoyuko">
             <pose>0 0 0 0 0 0</pose>
             <visualize>true</visualize>
             <update_rate>10</update_rate>
             <ray>
               <scan>
                 <horizontal>
                   <samples>720</samples>
                   <resolution>1</resolution>
                   <min_angle>0</min_angle>
                   <max_angle>6.283185</max_angle>
                 </horizontal>
               </scan>
               <range>
                 <min>0.10</min>
                 <max>6</max>
                 <resolution>0.01</resolution>
               </range>
             </ray>
             <plugin name="gazebo_ros_head_hokuyo_controller" filename="libgazebo_ros_laser.so">
               <topicName>myrobot/laser/scan</topicName>
               <frameName>base_link</frameName>
             </plugin>
           </sensor>
         </gazebo>

         <!--imu gazebo-->
         <gazebo>
           <plugin name="imu_controller" filename="libhector_gazebo_ros_imu.so">
             <robotNamespace>/</robotNamespace>
             <updateRate>20.0</updateRate>
             <bodyName>base_link</bodyName>
             <topicName>imu</topicName>
             <accelDrift>0.005 0.005 0.005</accelDrift>
             <accelGaussianNoise>0.005 0.005 0.005</accelGaussianNoise>
             <rateDrift>0.005 0.005 0.005 </rateDrift>
             <rateGaussianNoise>0.005 0.005 0.005 </rateGaussianNoise>
             <headingDrift>0.005</headingDrift>
             <headingGaussianNoise>0.005</headingGaussianNoise>
           </plugin>
         </gazebo>

       <gazebo reference="base_link">
           <turnGravityOff>false</turnGravityOff>
         </gazebo>
       <!--differential_drive_controller-->
     <gazebo>
       <plugin name="differential_drive_controller" filename="libgazebo_ros_diff_drive.so">
         <alwaysOn>true</alwaysOn>
         <updateRate>20.0</updateRate>
         <leftJoint>joint_left_wheel</leftJoint>
         <rightJoint>joint_right_wheel</rightJoint>
         <wheelSeparation>0.54</wheelSeparation>
         <wheelDiameter>0.13</wheelDiameter>
         <torque>20</torque>
         <commandTopic>cmd_vel</commandTopic>
         <odometryTopic>odom</odometryTopic>
         <odometryFrame>odom</odometryFrame>
         <robotBaseFrame>base_link</robotBaseFrame>
       </plugin>
     </gazebo>
       <!--gazebo color-->
       <gazebo reference="base_link">
         <material>Gazebo/Blue</material>
       </gazebo>
       <gazebo reference="right_wheel">
         <material>Gazebo/Red</material>
       </gazebo>
       <gazebo reference="left_wheel">
         <material>Gazebo/Red</material>
       </gazebo>
       <gazebo reference="camera_link">
         <material>Gazebo/Black</material>
       </gazebo>

     </robot>
