<?xml version='1.0'?>
<robot name="myrobot">

  <!-- Base Link -->
  <link name="base_link">
    <visual>
      <origin xyz="-0.195 0 0" rpy="0 0 0" />
      <geometry>
          <box size="0.505 0.54 0.02"/>
      </geometry>
      <material name="blue">
        <color rgba="0 1 1 1"/>
      </material>
    </visual>
    <!-- Base collision, mass and inertia -->
    <collision>
      <origin xyz="-0.195 0 0" rpy="0 0 0" />
      <geometry>
          <box size="0.505 0.54 0.02"/>
      </geometry>
    </collision>
    <inertial>
      <mass value="10"/>
      <inertia ixx="0.36" ixy="0.0" ixz="0.0" iyy="2000100.31" iyz="0.0" izz="0.67"/>
    </inertial>
    <!--fronthead-->
    <visual name="fronthead">
      <origin xyz="0.05 0 0.01" rpy="0 0 0" />
      <geometry>
        <box size="0.2 0.34 0.005"/>
      </geometry>
    </visual>
    <!-- fronthead collision, mass and inertia -->
    <collision>
      <origin xyz="0.05 0 0.01" rpy="0 0 0" />
      <geometry>
        <box size="0.2 0.34 0.005"/>
      </geometry>
    </collision>
    <inertial>
      <mass value="0.4"/>
      <inertia ixx="0.004" ixy="0.0" ixz="0.0" iyy="0.001" iyz="0.0" izz="0.005"/>
    </inertial>
    <!--laserbase-->
    <visual name="laserbase">
      <origin xyz="0 0 0.152" rpy="0 0 0" />
      <geometry>
        <box size="0.02 0.02 0.3"/>
      </geometry>
    </visual>
    <!-- laserbase collision, mass and inertia -->
    <collision>
      <origin xyz="0 0 0.152" rpy="0 0 0" />
      <geometry>
        <box size="0.02 0.02 0.3"/>
      </geometry>
    </collision>
    <inertial>
      <mass value="0.3"/>
      <inertia ixx="0.002" ixy="0.0" ixz="0.0" iyy="0.002" iyz="0.0" izz="0.000"/>
    </inertial>
    <!--laserplate-->
    <visual name="laserplate">
      <origin xyz="0 0 0.302" rpy="0 0 0" />
      <geometry>
        <box size="0.2 0.2 0.005"/>
      </geometry>
    </visual>
    <!-- laserplate collision, mass and inertia -->
    <collision>
      <origin xyz="0 0 0.302" rpy="0 0 0" />
      <geometry>
        <box size="0.2 0.2 0.005"/>
      </geometry>
    </collision>
    <inertial>
      <mass value="0.24"/>
      <inertia ixx="0.000" ixy="0.0" ixz="0.0" iyy="0.000" iyz="0.0" izz="0.002"/>
    </inertial>

    <!-- Caster -->
    <visual name="caster">
      <origin xyz="-0.40 0 0" rpy="0 0 0" />
      <geometry>
        <cylinder length="0.13" radius="0.006" />
      </geometry>
    </visual>
    <!-- Caster collision, mass and inertia -->
    <collision>
      <origin xyz="-0.40 0 0" rpy="0 0 0" />
      <geometry>
        <cylinder length="0.13" radius="0.006" />
      </geometry>
    </collision>
    <inertial>
      <mass value="1"/>
      <inertia ixx="0.0001" ixy="0.0" ixz="0.0" iyy="0.0001" iyz="0.0" izz="0.0001"/>
    </inertial>

  </link>

  <!-- Right Wheel -->
  <link name="right_wheel">
         <visual>
           <origin xyz="0 0 0" rpy="1.570795 0 0" />
           <geometry>
               <cylinder length="0.01" radius="0.065" />
           </geometry>
           <material name="darkgray">
             <color rgba=".1 .1 .2 1"/>
           </material>
         </visual>
         <!-- Right Wheel collision, mass and inertia -->
         <collision>
           <origin xyz="0 0 0" rpy="1.570795 0 0" />
           <geometry>
               <cylinder length="0.01" radius="0.065" />
           </geometry>
         </collision>
         <inertial>
           <mass value="0.1"/>
           <inertia ixx="0.0003" ixy="0.0" ixz="0.0" iyy="0.0003" iyz="0.0" izz="0.0007"/>
         </inertial>

       </link>

  <!-- Right Wheel joint -->
  <joint name="joint_right_wheel" type="continuous">
         <parent link="base_link"/>
         <child link="right_wheel"/>
         <origin xyz="0 -0.28 0" rpy="0 0 0" />
         <axis xyz="0 1 0" />
         <limit effort="10000" velocity="1000"/>
         <joint_properties damping="1.0" friction="1.0"/>
       </joint>

  <!-- Left Wheel -->
  <link name="left_wheel">
         <visual>
           <origin xyz="0 0 0" rpy="1.570795 0 0" />
           <geometry>
               <cylinder length="0.01" radius="0.065" />
           </geometry>
           <material name="darkgray">
             <color rgba=".2 .2 .2 1"/>
           </material>
         </visual>
         <!-- Left Wheel collision, mass and inertia -->
         <collision>
           <origin xyz="0 0 0" rpy="1.570795 0 0" />
           <geometry>
               <cylinder length="0.01" radius="0.065" />
           </geometry>
         </collision>
         <inertial>
           <mass value="0.1"/>
           <inertia ixx="0.0003" ixy="0.0" ixz="0.0" iyy="0.0003" iyz="0.0" izz="0.0007"/>
         </inertial>
       </link>

  <!-- Left Wheel joint -->
  <joint name="joint_left_wheel" type="continuous">
         <parent link="base_link"/>
         <child link="left_wheel"/>
         <origin xyz="0 0.28 0" rpy="0 0 0" />
         <axis xyz="0 1 0" />
         <limit effort="10000" velocity="1000"/>
         <joint_properties damping="1.0" friction="1.0"/>
       </joint>

  <!--kinect-->
  <link name="camera_link">
           <collision>
             <origin xyz="0 0 0" rpy="0 0 0"/>
             <geometry>
               <box size="0.1 0.1 0.1"/>
             </geometry>
           </collision>

           <visual>
             <origin xyz="0 0 0" rpy="0 0 1.57"/>
             <geometry>
               <mesh filename="package://husky_description/meshes/accessories/kinect.dae"/>
             </geometry>
             <material name="black"/>
           </visual>

           <inertial>
             <mass value="1e-5" />
             <inertia ixx="1e-6" ixy="0" ixz="0" iyy="1e-6" iyz="0" izz="1e-6" />
           </inertial>
         </link>

  <!--kinect joint-->
  <joint name="camera_joint" type="fixed">
           <origin xyz="0.05 0 0.04" rpy="0 0 0"/>
           <parent link="base_link"/>
           <child link="camera_link"/>
         </joint>

             <!-- Hokuyo Laser -->

   <!--Laser-->
   <link name="hokuyo_link">
               <collision>
                 <origin xyz="0 0 0" rpy="0 0 0"/>
                 <geometry>
               <box size="0.1 0.1 0.1"/>
                 </geometry>
               </collision>

               <visual>
                 <origin xyz="0 0 0" rpy="1.57 0 3.14"/>
                 <geometry>
                   <mesh filename="package://myrobot/meshes/rplidar.dae"/>
                 </geometry>
               </visual>

               <inertial>
                 <mass value="1e-5" />
                 <inertia ixx="1e-6" ixy="0" ixz="0" iyy="1e-6" iyz="0" izz="1e-6" />
               </inertial>
             </link>

  <!--Laser joint-->
  <joint name="hokuyo_joint" type="fixed">
               <origin xyz="-0.05 0 .325" rpy="0 0 0"/>
               <parent link="base_link"/>
               <child link="hokuyo_link"/>
         </joint>
</robot>
